Workbook

Sheet Matriz de riesgo SD
A1: Codigo | B1: Responsables | C1: Proceso | D1: AreasTrabajo | E1: AvancePlanificado | F1: AvanceReal | G1: Descripcion | H1: FechaInicio | I1: FechaVencimiento
A2: SD 2187 | B2: Lizama Donoso Andrés A. (AALIZAMA@collahuasi.cl);Melo Miranda Fernando A. (FMELO@collahuasi.cl);Meriño Martinez Máximo E. (MEMERINO@collahuasi.cl) | C2: Puerto | D2: Planta Filtros | E2: 0 | F2: 0 | G2: Mantención Sementral 310FL002 | H2: =Tareas!$H$2 -> 43992 | I2: 44034

Sheet Tareas
A1: Nombre de tarea | B1: Ponderacion | C1: Asignado a | D1: Actividad | E1: AvancePlanificado | F1: AvanceReal | G1: Descripción | H1: Fecha de inicio | I1: Fecha de vencimiento | J1: Activo | K1: Validada | L1: Comentarios | M1: ID | N1: FREC | O1: DURACIÓN
A2: 01 Creacion y difusion Matriz de riesgo SD Mantención | B2: =IF(Tareas[[#This Row],[ID]]=1,100/SUM($M$2:$M$24),0) -> 4.7619048 | C2: Meriño Martinez Máximo E. (MEMERINO@collahuasi.cl) | D2: A. PLANIFICACION DEL MANTENIMIENTO | E2: =(IF(I2<=TODAY(),1,0))*B2 -> 4.7619048 | F2: 4.8 | H2: =I2-O2 -> 43992 | I2: ='Matriz de riesgo SD'!$I$2-N2 -> 43994 | J2: Sí | K2: 0 | M2: =IF(Tareas[[#This Row],[Activo]]="sí",1,0) -> 1 | N2: 40 | O2: 2
A3: 02 Revision Aprendizajes (caja 6) mantención anterior | B3: =IF(Tareas[[#This Row],[ID]]=1,100/SUM($M$2:$M$24),0) -> 4.7619048 | C3: Meriño Martinez Máximo E. (MEMERINO@collahuasi.cl) | D3: A. PLANIFICACION DEL MANTENIMIENTO | E3: =(IF(I3<=TODAY(),1,0))*B3 -> 4.7619048 | F3: 4.8 | H3: =I3-O3 -> 43992 | I3: ='Matriz de riesgo SD'!$I$2-N3 -> 43994 | J3: Sí | K3: 0 | M3: =IF(Tareas[[#This Row],[Activo]]="sí",1,0) -> 1 | N3: 40 | O3: 2
A4: 03 Generacion de carta gantt base para mantencion | B4: =IF(Tareas[[#This Row],[ID]]=1,100/SUM($M$2:$M$24),0) -> 4.7619048 | C4: Meriño Martinez Máximo E. (MEMERINO@collahuasi.cl) | D4: A. PLANIFICACION DEL MANTENIMIENTO | E4: =(IF(I4<=TODAY(),1,0))*B4 -> 4.7619048 | F4: 4.8 | H4: =I4-O4 -> 43990 | I4: ='Matriz de riesgo SD'!$I$2-N4 -> 43994 | J4: Sí | K4: 0 | L4: CARTA TIPO | M4: =IF(Tareas[[#This Row],[Activo]]="sí",1,0) -> 1 | N4: 40 | O4: 4
A5: 04 Revision de WR para mantencion | B5: =IF(Tareas[[#This Row],[ID]]=1,100/SUM($M$2:$M$24),0) -> 4.7619048 | C5: Meriño Martinez Máximo E. (MEMERINO@collahuasi.cl) | D5: A. PLANIFICACION DEL MANTENIMIENTO | E5: =(IF(I5<=TODAY(),1,0))*B5 -> 4.7619048 | F5: 4.8 | H5: =I5-O5 -> 44001 | I5: ='Matriz de riesgo SD'!$I$2-N5 -> 44004 | J5: Sí | K5: 0 | M5: =IF(Tareas[[#This Row],[Activo]]="sí",1,0) -> 1 | N5: 30 | O5: 3
A6: 05 Revision de MST para la mantención | B6: =IF(Tareas[[#This Row],[ID]]=1,100/SUM($M$2:$M$24),0) -> 4.7619048 | C6: Meriño Martinez Máximo E. (MEMERINO@collahuasi.cl) | D6: A. PLANIFICACION DEL MANTENIMIENTO | E6: =(IF(I6<=TODAY(),1,0))*B6 -> 4.7619048 | F6: 4.8 | H6: =I6-O6 -> 44001 | I6: ='Matriz de riesgo SD'!$I$2-N6 -> 44004 | J6: Sí | K6: 0 | M6: =IF(Tareas[[#This Row],[Activo]]="sí",1,0) -> 1 | N6: 30 | O6: 3
A7: 06 Revision de Backlog (Ots derivadas del corto plazo para Mantenciones SD) | B7: =IF(Tareas[[#This Row],[ID]]=1,100/SUM($M$2:$M$24),0) -> 0 | C7: Meriño Martinez Máximo E. (MEMERINO@collahuasi.cl) | D7: A. PLANIFICACION DEL MANTENIMIENTO | E7: =(IF(I7<=TODAY(),1,0))*B7 -> 0 | F7: 0 | H7: =I7-O7 -> 44001 | I7: ='Matriz de riesgo SD'!$I$2-N7 -> 44004 | J7: No | K7: 0 | M7: =IF(Tareas[[#This Row],[Activo]]="sí",1,0) -> 0 | N7: 30 | O7: 3
A8: 07 Recepcion actividades Proyectos (Formulario autorizado) | B8: =IF(Tareas[[#This Row],[ID]]=1,100/SUM($M$2:$M$24),0) -> 0 | C8: Meriño Martinez Máximo E. (MEMERINO@collahuasi.cl) | D8: A. PLANIFICACION DEL MANTENIMIENTO | E8: =(IF(I8<=TODAY(),1,0))*B8 -> 0 | F8: 0 | H8: =I8-O8 -> 44001 | I8: ='Matriz de riesgo SD'!$I$2-N8 -> 44004 | J8: No | K8: 0 | M8: =IF(Tareas[[#This Row],[Activo]]="sí",1,0) -> 0 | N8: 30 | O8: 3
A9: 08 Recepcion actividades desde WR (Formulario autorizado) | B9: =IF(Tareas[[#This Row],[ID]]=1,100/SUM($M$2:$M$24),0) -> 4.7619048 | C9: Meriño Martinez Máximo E. (MEMERINO@collahuasi.cl) | D9: A. PLANIFICACION DEL MANTENIMIENTO | E9: =(IF(I9<=TODAY(),1,0))*B9 -> 4.7619048 | F9: 4.8 | H9: =I9-O9 -> 44002 | I9: ='Matriz de riesgo SD'!$I$2-N9 -> 44004 | J9: Sí | K9: 0 | M9: =IF(Tareas[[#This Row],[Activo]]="sí",1,0) -> 1 | N9: 30 | O9: 2
A10: 09 Creacion de Ots Padres por equipos | B10: =IF(Tareas[[#This Row],[ID]]=1,100/SUM($M$2:$M$24),0) -> 4.7619048 | C10: Meriño Martinez Máximo E. (MEMERINO@collahuasi.cl) | D10: A. PLANIFICACION DEL MANTENIMIENTO | E10: =(IF(I10<=TODAY(),1,0))*B10 -> 4.7619048 | F10: 4.8 | H10: =I10-O10 -> 44003 | I10: ='Matriz de riesgo SD'!$I$2-N10 -> 44004 | J10: Sí | K10: 0 | M10: =IF(Tareas[[#This Row],[Activo]]="sí",1,0) -> 1 | N10: 30 | O10: 1
A11: 10 Creacion de Ordenes de trabajo y compromiso en ellipse para los Grupos | B11: =IF(Tareas[[#This Row],[ID]]=1,100/SUM($M$2:$M$24),0) -> 4.7619048 | C11: Meriño Martinez Máximo E. (MEMERINO@collahuasi.cl) | D11: A. PLANIFICACION DEL MANTENIMIENTO | E11: =(IF(I11<=TODAY(),1,0))*B11 -> 4.7619048 | F11: 4.8 | H11: =I11-O11 -> 44022 | I11: ='Matriz de riesgo SD'!$I$2-N11 -> 44023 | J11: Sí | K11: 0 | M11: =IF(Tareas[[#This Row],[Activo]]="sí",1,0) -> 1 | N11: 11 | O11: 1
A12: 11 Generar calendario de Hitos Planificacion Mantenimiento | B12: =IF(Tareas[[#This Row],[ID]]=1,100/SUM($M$2:$M$24),0) -> 4.7619048 | C12: Meriño Martinez Máximo E. (MEMERINO@collahuasi.cl) | D12: A. PLANIFICACION DEL MANTENIMIENTO | E12: =(IF(I12<=TODAY(),1,0))*B12 -> 4.7619048 | F12: 4.8 | H12: =I12-O12 -> 44003 | I12: ='Matriz de riesgo SD'!$I$2-N12 -> 44004 | J12: Sí | K12: 0 | M12: =IF(Tareas[[#This Row],[Activo]]="sí",1,0) -> 1 | N12: 30 | O12: 1
A13: 12 Preparacion de reportabilidad avances y curva "S" | B13: =IF(Tareas[[#This Row],[ID]]=1,100/SUM($M$2:$M$24),0) -> 4.7619048 | C13: Meriño Martinez Máximo E. (MEMERINO@collahuasi.cl) | D13: A. PLANIFICACION DEL MANTENIMIENTO | E13: =(IF(I13<=TODAY(),1,0))*B13 -> 4.7619048 | F13: 0 | H13: =I13-O13 -> 44023 | I13: ='Matriz de riesgo SD'!$I$2-N13 -> 44028 | J13: Sí | K13: 0 | M13: =IF(Tareas[[#This Row],[Activo]]="sí",1,0) -> 1 | N13: 6 | O13: 5
A14: 13 Generar y controlar "Mapa Requerimientos". | B14: =IF(Tareas[[#This Row],[ID]]=1,100/SUM($M$2:$M$24),0) -> 4.7619048 | C14: Meriño Martinez Máximo E. (MEMERINO@collahuasi.cl) | D14: A. PLANIFICACION DEL MANTENIMIENTO | E14: =(IF(I14<=TODAY(),1,0))*B14 -> 4.7619048 | F14: 4.8 | H14: =I14-O14 -> 44005 | I14: ='Matriz de riesgo SD'!$I$2-N14 -> 44006 | J14: Sí | K14: 0 | M14: =IF(Tareas[[#This Row],[Activo]]="sí",1,0) -> 1 | N14: 28 | O14: 1
A15: 14 Reunion: Definicion de Actividades de mantencion con involucrados por equipos | B15: =IF(Tareas[[#This Row],[ID]]=1,100/SUM($M$2:$M$24),0) -> 4.7619048 | C15: Meriño Martinez Máximo E. (MEMERINO@collahuasi.cl) | D15: A. PLANIFICACION DEL MANTENIMIENTO | E15: =(IF(I15<=TODAY(),1,0))*B15 -> 4.7619048 | F15: 4.8 | H15: =I15-O15 -> 44002 | I15: ='Matriz de riesgo SD'!$I$2-N15 -> 44004 | J15: Sí | K15: 0 | M15: =IF(Tareas[[#This Row],[Activo]]="sí",1,0) -> 1 | N15: 30 | O15: 2
A16: 15 Envio carta gantt en revision preliminar - Rev. A-B-C | B16: =IF(Tareas[[#This Row],[ID]]=1,100/SUM($M$2:$M$24),0) -> 4.7619048 | C16: Meriño Martinez Máximo E. (MEMERINO@collahuasi.cl) | D16: A. PLANIFICACION DEL MANTENIMIENTO | E16: =(IF(I16<=TODAY(),1,0))*B16 -> 4.7619048 | F16: 4.8 | H16: =I16-O16 -> 44005 | I16: ='Matriz de riesgo SD'!$I$2-N16 -> 44006 | J16: Sí | K16: 0 | M16: =IF(Tareas[[#This Row],[Activo]]="sí",1,0) -> 1 | N16: 28 | O16: 1
... A24: 23 Retiro de Ots del programa por parte de CMDIC y ESED ejecutantes | B24: =IF(Tareas[[#This Row],[ID]]=1,100/SUM($M$2:$M$24),0) -> 4.7619048 | C24: Hurtado Olcay Marcelo S (MSHURTADO@collahuasi.cl) | D24: A. PLANIFICACION DEL MANTENIMIENTO | E24: =(IF(I24<=TODAY(),1,0))*B24 -> 4.7619048 | F24: 0 | H24: =I24-O24 -> 44021 | I24: ='Matriz de riesgo SD'!$I$2-N24 -> 44022 | J24: Sí | K24: 0 | M24: =IF(Tareas[[#This Row],[Activo]]="sí",1,0) -> 1 | N24: 12 | O24: 1
A25: 01 Revision y confirmacion de actividades programadas - ELECTRICOS | B25: =IF(Tareas[[#This Row],[ID]]=1,100/SUM($M$25:$M$32),0) -> 25 | C25: Hurtado Olcay Marcelo S (MSHURTADO@collahuasi.cl) | D25: B. REVISION Y VALIDACION ACTIVIDADES PROGRAMADAS | E25: =(IF(I25<=TODAY(),1,0))*B25 -> 25 | F25: 25 | H25: =I25-O25 -> 44001 | I25: ='Matriz de riesgo SD'!$I$2-N25 -> 44004 | J25: Sí | K25: 0 | M25: =IF(Tareas[[#This Row],[Activo]]="sí",1,0) -> 1 | N25: 30 | O25: 3
A26: 02 Revision y confirmacion de actividades programadas - DCS | B26: =IF(Tareas[[#This Row],[ID]]=1,100/SUM($M$25:$M$32),0) -> 0 | C26: Hurtado Olcay Marcelo S (MSHURTADO@collahuasi.cl) | D26: B. REVISION Y VALIDACION ACTIVIDADES PROGRAMADAS | E26: =(IF(I26<=TODAY(),1,0))*B26 -> 0 | F26: 0 | H26: =I26-O26 -> 44001 | I26: ='Matriz de riesgo SD'!$I$2-N26 -> 44004 | J26: No | K26: 0 | M26: =IF(Tareas[[#This Row],[Activo]]="sí",1,0) -> 0 | N26: 30 | O26: 3
A27: 03 Revision y confirmacion de actividades programadas - INSTRUMENTACION | B27: =IF(Tareas[[#This Row],[ID]]=1,100/SUM($M$25:$M$32),0) -> 25 | C27: Hurtado Olcay Marcelo S (MSHURTADO@collahuasi.cl) | D27: B. REVISION Y VALIDACION ACTIVIDADES PROGRAMADAS | E27: =(IF(I27<=TODAY(),1,0))*B27 -> 25 | F27: 25 | H27: =I27-O27 -> 44001 | I27: ='Matriz de riesgo SD'!$I$2-N27 -> 44004 | J27: Sí | K27: 0 | M27: =IF(Tareas[[#This Row],[Activo]]="sí",1,0) -> 1 | N27: 30 | O27: 3
A28: 04 Revision y confirmacion de actividades programadas - MECANICOS | B28: =IF(Tareas[[#This Row],[ID]]=1,100/SUM($M$25:$M$32),0) -> 25 | C28: Hurtado Olcay Marcelo S (MSHURTADO@collahuasi.cl) | D28: B. REVISION Y VALIDACION ACTIVIDADES PROGRAMADAS | E28: =(IF(I28<=TODAY(),1,0))*B28 -> 25 | F28: 25 | H28: =I28-O28 -> 44001 | I28: ='Matriz de riesgo SD'!$I$2-N28 -> 44004 | J28: Sí | K28: 0 | M28: =IF(Tareas[[#This Row],[Activo]]="sí",1,0) -> 1 | N28: 30 | O28: 3
A29: 05 Revision y confirmacion de actividades programadas - LUBRICACION | B29: =IF(Tareas[[#This Row],[ID]]=1,100/SUM($M$25:$M$32),0) -> 25 | C29: Hurtado Olcay Marcelo S (MSHURTADO@collahuasi.cl) | D29: B. REVISION Y VALIDACION ACTIVIDADES PROGRAMADAS | E29: =(IF(I29<=TODAY(),1,0))*B29 -> 25 | F29: 25 | H29: =I29-O29 -> 44001 | I29: ='Matriz de riesgo SD'!$I$2-N29 -> 44004 | J29: Sí | K29: 0 | M29: =IF(Tareas[[#This Row],[Activo]]="sí",1,0) -> 1 | N29: 30 | O29: 3
A30: 06 Revision y confirmacion de actividades programadas - PREDICTIVO / CONFIABILIDAD | B30: =IF(Tareas[[#This Row],[ID]]=1,100/SUM($M$25:$M$32),0) -> 0 | C30: Meriño Martinez Máximo E. (MEMERINO@collahuasi.cl) | D30: B. REVISION Y VALIDACION ACTIVIDADES PROGRAMADAS | E30: =(IF(I30<=TODAY(),1,0))*B30 -> 0 | F30: 0 | H30: =I30-O30 -> 44001 | I30: ='Matriz de riesgo SD'!$I$2-N30 -> 44004 | J30: No | K30: 0 | M30: =IF(Tareas[[#This Row],[Activo]]="sí",1,0) -> 0 | N30: 30 | O30: 3
A31: 07 Revision y confirmacion de actividades programadas - METALURGIA | B31: =IF(Tareas[[#This Row],[ID]]=1,100/SUM($M$25:$M$32),0) -> 0 | C31: Meriño Martinez Máximo E. (MEMERINO@collahuasi.cl) | D31: B. REVISION Y VALIDACION ACTIVIDADES PROGRAMADAS | E31: =(IF(I31<=TODAY(),1,0))*B31 -> 0 | F31: 0 | H31: =I31-O31 -> 44001 | I31: ='Matriz de riesgo SD'!$I$2-N31 -> 44004 | J31: No | K31: 0 | M31: =IF(Tareas[[#This Row],[Activo]]="sí",1,0) -> 0 | N31: 30 | O31: 3
A32: 08 Revision y confirmacion de actividades programadas - PROYECTOS | B32: =IF(Tareas[[#This Row],[ID]]=1,100/SUM($M$25:$M$32),0) -> 0 | C32: Meriño Martinez Máximo E. (MEMERINO@collahuasi.cl) | D32: B. REVISION Y VALIDACION ACTIVIDADES PROGRAMADAS | E32: =(IF(I32<=TODAY(),1,0))*B32 -> 0 | F32: 0 | H32: =I32-O32 -> 44001 | I32: ='Matriz de riesgo SD'!$I$2-N32 -> 44004 | J32: No | K32: 0 | M32: =IF(Tareas[[#This Row],[Activo]]="sí",1,0) -> 0 | N32: 30 | O32: 3
A33: 01 Revision de Registros de incidentes SSO, mantenciones anteriores | B33: =IF(Tareas[[#This Row],[ID]]=1,100/SUM($M$33:$M$46),0) -> 9.0909091 | C33: Meriño Martinez Máximo E. (MEMERINO@collahuasi.cl) | D33: C. GESTION DE SEGURIDAD Y SALUD | E33: =(IF(I33<=TODAY(),1,0))*B33 -> 9.0909091 | F33: 9.1 | H33: =I33-O33 -> 43992 | I33: ='Matriz de riesgo SD'!$I$2-N33 -> 43994 | J33: Sí | K33: 0 | M33: =IF(Tareas[[#This Row],[Activo]]="sí",1,0) -> 1 | N33: 40 | O33: 2
A34: 02 Programa de trabajo Seguridad y Salud | B34: =IF(Tareas[[#This Row],[ID]]=1,100/SUM($M$33:$M$46),0) -> 9.0909091 | C34: Meriño Martinez Máximo E. (MEMERINO@collahuasi.cl) | D34: C. GESTION DE SEGURIDAD Y SALUD | E34: =(IF(I34<=TODAY(),1,0))*B34 -> 9.0909091 | F34: 9.1 | H34: =I34-O34 -> 43991 | I34: ='Matriz de riesgo SD'!$I$2-N34 -> 43994 | J34: Sí | K34: 0 | M34: =IF(Tareas[[#This Row],[Activo]]="sí",1,0) -> 1 | N34: 40 | O34: 3
A35: 03 Reunion N°1 - Gestion de Riesgos asociados a la Mantencion | B35: =IF(Tareas[[#This Row],[ID]]=1,100/SUM($M$33:$M$46),0) -> 9.0909091 | C35: Meriño Martinez Máximo E. (MEMERINO@collahuasi.cl) | D35: C. GESTION DE SEGURIDAD Y SALUD | E35: =(IF(I35<=TODAY(),1,0))*B35 -> 9.0909091 | F35: 9.1 | H35: =I35-O35 -> 44003 | I35: ='Matriz de riesgo SD'!$I$2-N35 -> 44004 | J35: Sí | K35: 0 | M35: =IF(Tareas[[#This Row],[Activo]]="sí",1,0) -> 1 | N35: 30 | O35: 1
A36: 04 Reunion N°2 - Gestion de Riesgos asociados a la Mantencion | B36: =IF(Tareas[[#This Row],[ID]]=1,100/SUM($M$33:$M$46),0) -> 9.0909091 | C36: Meriño Martinez Máximo E. (MEMERINO@collahuasi.cl) | D36: C. GESTION DE SEGURIDAD Y SALUD | E36: =(IF(I36<=TODAY(),1,0))*B36 -> 9.0909091 | F36: 0 | H36: =I36-O36 -> 44021 | I36: ='Matriz de riesgo SD'!$I$2-N36 -> 44022 | J36: Sí | K36: 0 | M36: =IF(Tareas[[#This Row],[Activo]]="sí",1,0) -> 1 | N36: 12 | O36: 1
A37: 05 Revision, actualización de diagramas de bloqueo | B37: =IF(Tareas[[#This Row],[ID]]=1,100/SUM($M$33:$M$46),0) -> 9.0909091 | C37: Meriño Martinez Máximo E. (MEMERINO@collahuasi.cl) | D37: C. GESTION DE SEGURIDAD Y SALUD | E37: =(IF(I37<=TODAY(),1,0))*B37 -> 9.0909091 | F37: 0 | H37: =I37-O37 -> 44013 | I37: ='Matriz de riesgo SD'!$I$2-N37 -> 44014 | J37: Sí | K37: 0 | M37: =IF(Tareas[[#This Row],[Activo]]="sí",1,0) -> 1 | N37: 20 | O37: 1
A38: 06 Envio Plan de bloqueo | B38: =IF(Tareas[[#This Row],[ID]]=1,100/SUM($M$33:$M$46),0) -> 9.0909091 | C38: Meriño Martinez Máximo E. (MEMERINO@collahuasi.cl) | D38: C. GESTION DE SEGURIDAD Y SALUD | E38: =(IF(I38<=TODAY(),1,0))*B38 -> 9.0909091 | F38: 0 | H38: =I38-O38 -> 44015 | I38: ='Matriz de riesgo SD'!$I$2-N38 -> 44016 | J38: Sí | K38: 0 | M38: =IF(Tareas[[#This Row],[Activo]]="sí",1,0) -> 1 | N38: 18 | O38: 1
A39: 07 Reunion de Bloqueo | B39: =IF(Tareas[[#This Row],[ID]]=1,100/SUM($M$33:$M$46),0) -> 9.0909091 | C39: Meriño Martinez Máximo E. (MEMERINO@collahuasi.cl) | D39: C. GESTION DE SEGURIDAD Y SALUD | E39: =(IF(I39<=TODAY(),1,0))*B39 -> 9.0909091 | F39: 0 | H39: =I39-O39 -> 44022 | I39: ='Matriz de riesgo SD'!$I$2-N39 -> 44023 | J39: Sí | K39: 0 | M39: =IF(Tareas[[#This Row],[Activo]]="sí",1,0) -> 1 | N39: 11 | O39: 1
A40: 08 Validación de actividades en Matriz de Riesgo y sus controles / ELECTRICOS | B40: =IF(Tareas[[#This Row],[ID]]=1,100/SUM($M$33:$M$46),0) -> 9.0909091 | C40: Hurtado Olcay Marcelo S (MSHURTADO@collahuasi.cl) | D40: C. GESTION DE SEGURIDAD Y SALUD | E40: =(IF(I40<=TODAY(),1,0))*B40 -> 9.0909091 | F40: 0 | H40: =I40-O40 -> 44021 | I40: ='Matriz de riesgo SD'!$I$2-N40 -> 44022 | J40: Sí | K40: 0 | M40: =IF(Tareas[[#This Row],[Activo]]="sí",1,0) -> 1 | N40: 12 | O40: 1
A41: 09 Validación de actividades en Matriz de Riesgo y sus controles / DCS | B41: =IF(Tareas[[#This Row],[ID]]=1,100/SUM($M$33:$M$46),0) -> 0 | C41: Hurtado Olcay Marcelo S (MSHURTADO@collahuasi.cl) | D41: C. GESTION DE SEGURIDAD Y SALUD | E41: =(IF(I41<=TODAY(),1,0))*B41 -> 0 | F41: 0 | H41: =I41-O41 -> 44017 | I41: ='Matriz de riesgo SD'!$I$2-N41 -> 44018 | J41: No | K41: 0 | M41: =IF(Tareas[[#This Row],[Activo]]="sí",1,0) -> 0 | N41: 16 | O41: 1
A42: 10 Validación de actividades en Matriz de Riesgo y sus controles / INSTRUMENTACION | B42: =IF(Tareas[[#This Row],[ID]]=1,100/SUM($M$33:$M$46),0) -> 9.0909091 | C42: Hurtado Olcay Marcelo S (MSHURTADO@collahuasi.cl) | D42: C. GESTION DE SEGURIDAD Y SALUD | E42: =(IF(I42<=TODAY(),1,0))*B42 -> 9.0909091 | F42: 0 | H42: =I42-O42 -> 44017 | I42: ='Matriz de riesgo SD'!$I$2-N42 -> 44018 | J42: Sí | K42: 0 | M42: =IF(Tareas[[#This Row],[Activo]]="sí",1,0) -> 1 | N42: 16 | O42: 1
A43: 11 Validación de actividades en Matriz de Riesgo y sus controles / MECANICOS | B43: =IF(Tareas[[#This Row],[ID]]=1,100/SUM($M$33:$M$46),0) -> 9.0909091 | C43: Hurtado Olcay Marcelo S (MSHURTADO@collahuasi.cl) | D43: C. GESTION DE SEGURIDAD Y SALUD | E43: =(IF(I43<=TODAY(),1,0))*B43 -> 9.0909091 | F43: 0 | H43: =I43-O43 -> 44017 | I43: ='Matriz de riesgo SD'!$I$2-N43 -> 44018 | J43: Sí | K43: 0 | M43: =IF(Tareas[[#This Row],[Activo]]="sí",1,0) -> 1 | N43: 16 | O43: 1
A44: 12 Validación de actividades en Matriz de Riesgo y sus controles / LUBRICACION | B44: =IF(Tareas[[#This Row],[ID]]=1,100/SUM($M$33:$M$46),0) -> 9.0909091 | C44: Hurtado Olcay Marcelo S (MSHURTADO@collahuasi.cl) | D44: C. GESTION DE SEGURIDAD Y SALUD | E44: =(IF(I44<=TODAY(),1,0))*B44 -> 9.0909091 | F44: 0 | H44: =I44-O44 -> 44017 | I44: ='Matriz de riesgo SD'!$I$2-N44 -> 44018 | J44: Sí | K44: 0 | M44: =IF(Tareas[[#This Row],[Activo]]="sí",1,0) -> 1 | N44: 16 | O44: 1
... A46: 14 Validación de actividades en Matriz de Riesgo y sus controles / OPERACIONES | B46: =IF(Tareas[[#This Row],[ID]]=1,100/SUM($M$33:$M$46),0) -> 0 | C46: Meriño Martinez Máximo E. (MEMERINO@collahuasi.cl) | D46: C. GESTION DE SEGURIDAD Y SALUD | E46: =(IF(I46<=TODAY(),1,0))*B46 -> 0 | F46: 0 | H46: =I46-O46 -> 44013 | I46: ='Matriz de riesgo SD'!$I$2-N46 -> 44014 | J46: No | K46: 0 | M46: =IF(Tareas[[#This Row],[Activo]]="sí",1,0) -> 0 | N46: 20 | O46: 1
A47: 01 Plan Gestion de Residuos mantención | B47: =IF(Tareas[[#This Row],[ID]]=1,100/SUM($M$47:$M$50),0) -> 50 | C47: Hurtado Olcay Marcelo S (MSHURTADO@collahuasi.cl) | D47: D. GESTION MEDIO AMBIENTE | E47: =(IF(I47<=TODAY(),1,0))*B47 -> 50 | F47: 50 | H47: =I47-O47 -> 43998 | I47: ='Matriz de riesgo SD'!$I$2-N47 -> 43999 | J47: Sí | K47: 0 | M47: =IF(Tareas[[#This Row],[Activo]]="sí",1,0) -> 1 | N47: 35 | O47: 1
A48: 02 Solicitud de contenedor de residuos y layout de ubicación en Planta | B48: =IF(Tareas[[#This Row],[ID]]=1,100/SUM($M$47:$M$50),0) -> 0 | C48: Meriño Martinez Máximo E. (MEMERINO@collahuasi.cl) | D48: D. GESTION MEDIO AMBIENTE | E48: =(IF(I48<=TODAY(),1,0))*B48 -> 0 | F48: 0 | H48: =I48-O48 -> 44008 | I48: ='Matriz de riesgo SD'!$I$2-N48 -> 44009 | J48: No | K48: 0 | M48: =IF(Tareas[[#This Row],[Activo]]="sí",1,0) -> 0 | N48: 25 | O48: 1
...

Sheet Proceso
A1: ID | B1: Title | C1: l ids
A2: 1 | B2: Chancado y Transporte
A3: 2 | B3: Molienda
A4: 3 | B4: Chancado Pebbles
A5: 4 | B5: Lavado Pebbles
A6: 5 | B6: Flotación
A7: 6 | B7: Cal y Reactivos
A8: 7 | B8: Espesamiento
A9: 8 | B9: Tranque
A10: 9 | B10: Suministro y Calidad de Aguas
A11: 10 | B11: Mineroducto
A12: 11 | B12: Puerto
A13: 12 | B13: Lixiviación

Sheet Areas
A1: ID | B1: Title | C1: l ids
A2: 1 | B2: Concentradora Linea 1
A3: 2 | B3: Concentradora Linea 2
A4: 3 | B4: Concentradora Linea 3
A5: 4 | B5: Planta Lavado Pebbles
A6: 5 | B6: Planta chancado Pebbles
A7: 6 | B7: Planta CAL 1
A8: 7 | B8: Planta CAL 2
A9: 8 | B9: Planta Xantato
A10: 9 | B10: Planta Floculante
A11: 10 | B11: Chancado – Area 2 / Fase 2
A12: 11 | B12: Chancado – Area 3
A13: 12 | B13: Chancado Fase 1
... A23: 23 | B23: Area Seca

Sheet Responsables
A1: Chars
A2: Alfaro Morgado Leonardo I. (LIALFARO@collahuasi.cl)
A3: Avalos Gabilondo Luis E. (LEAVALOS@collahuasi.cl)
A4: Bugueño Gonzalez Julio A. (JABUGUENO@COLLAHUASI.CL)
A5: Cornejo Sanchez Fernando A. (FACORNEJO@collahuasi.cl)
A6: Donoso Nogales Pedro A. (PADONOSO@collahuasi.cl)
A7: Figueroa Garrido Fabian E. (FEFIGUEROA@collahuasi.cl)
A8: Gomez Araya Freddy Andres (FAGOMEZ@collahuasi.cl)
A9: Isasmendi Merino Javier I. (Javier.isasmendi@collahuasi.cl)
A10: Jara Inostroza Marcelo I. (MIJARA@collahuasi.cl)
A11: Lizama Donoso Andrés A. (AALIZAMA@collahuasi.cl)
A12: Melo Miranda Fernando A. (FMELO@collahuasi.cl)
... A105: Veloso Salazar Rene A. (RAVELOSO.ESED@collahuasi.cl)

Sheet Actividades
A1: ID | B1: Titulo | C1: Tareas | D1: AvancePlanificado | E1: AvanceReal | F1: Ponderacion | G1: PonderacionActividad
A2: 1 | B2: A. PLANIFICACION DEL MANTENIMIENTO | C2: =COUNTIF(Tareas!M2:M24,1) -> 21 | D2: =SUM(Tareas!E2:E24) -> 100 | E2: =SUM(Tareas!F2:F24) -> 57.6 | F2: =E2*G2/100 -> 5.76 | G2: 10
A3: 2 | B3: B. REVISION Y VALIDACION ACTIVIDADES PROGRAMADAS | C3: =COUNTIF(Tareas!M25:M32,1) -> 4 | D3: =SUM(Tareas!E25:E32) -> 100 | E3: =SUM(Tareas!F25:F32) -> 100 | F3: =E3*G3/100 -> 10 | G3: 10
A4: 3 | B4: C. GESTION DE SEGURIDAD Y SALUD | C4: =COUNTIF(Tareas!M33:M46,1) -> 11 | D4: =SUM(Tareas!E33:E46) -> 100 | E4: =SUM(Tareas!F33:F46) -> 27.3 | F4: =E4*G4/100 -> 2.73 | G4: 10
A5: 4 | B5: D. GESTION MEDIO AMBIENTE | C5: =COUNTIF(Tareas!M47:M50,1) -> 2 | D5: =SUM(Tareas!E47:E50) -> 100 | E5: =SUM(Tareas!F47:F50) -> 50 | F5: =E5*G5/100 -> 5 | G5: 10
A6: 5 | B6: E. DOTACIONES DEL MANTENIMIENTO | C6: =COUNTIF(Tareas!M51:M58,1) -> 7 | D6: =SUM(Tareas!E51:E58) -> 100 | E6: =SUM(Tareas!F51:F58) -> 28.6 | F6: =E6*G6/100 -> 2.86 | G6: 10
A7: 6 | B7: F. GESTION DE REPUESTOS Y MATERIALES | C7: =COUNTIF(Tareas!M59:M83,1) -> 22 | D7: =SUM(Tareas!E59:E83) -> 100 | E7: =SUM(Tareas!F59:F83) -> 54 | F7: =E7*G7/100 -> 5.4 | G7: 10
A8: 7 | B8: G. SERVICIOS AL PERSONAL | C8: =COUNTIF(Tareas!M84:M88,1) -> 4 | D8: =SUM(Tareas!E84:E88) -> 100 | E8: =SUM(Tareas!F84:F88) -> 75 | F8: =E8*G8/100 -> 3.75 | G8: 5
A9: 8 | B9: H. SERVICIOS DE APOYO Y EQUIPOS | C9: =COUNTIF(Tareas!M89:M99,1) -> 9 | D9: =SUM(Tareas!E89:E99) -> 100 | E9: =SUM(Tareas!F89:F99) -> 10 | F9: =E9*G9/100 -> 1 | G9: 10
A10: 9 | B10: I. GESTION DE PERSONAS | C10: =COUNTIF(Tareas!M100:M107,1) -> 4 | D10: =SUM(Tareas!E100:E107) -> 100 | E10: =SUM(Tareas!F100:F107) -> 0 | F10: =E10*G10/100 -> 0 | G10: 10
A11: 10 | B11: J. GESTION Y CONTROL DE LA EJECUCION DEL MANTENIMIENTO | C11: =COUNTIF(Tareas!M108:M116,1) -> 8 | D11: =SUM(Tareas!E108:E116) -> 100 | E11: =SUM(Tareas!F108:F116) -> 0 | F11: =E11*G11/100 -> 0 | G11: 10
A12: 11 | B12: K. GESTION CIERRE MANTENIMIENTO | C12: =COUNTIF(Tareas!M117:M128,1) -> 12 | D12: =SUM(Tareas!E117:E128) -> 100 | E12: =SUM(Tareas!F117:F128) -> 0 | F12: =E12*G12/100 -> 0 | G12: 5

Sheet Grafico
A1: ID | B1: Titulo | C1: Tareas | D1: AvancePlanificado | E1: AvanceReal | F1: REAL | G1: PonderacionActividad | H1: Planificado
A2: 1 | B2: A. PLANIFICACION DEL MANTENIMIENTO | C2: =Actividades!C2 -> 21 | D2: =Actividades!D2 -> 100 | E2: =Actividades!E2 -> 57.6 | F2: =Actividades!F2 -> 5.76 | G2: =Actividades!G2 -> 10 | H2: =D2*G2/100 -> 10
A3: 2 | B3: B. REVISION Y VALIDACION ACTIVIDADES PROGRAMADAS | C3: =Actividades!C3 -> 4 | D3: =Actividades!D3 -> 100 | E3: =Actividades!E3 -> 100 | F3: =Actividades!F3 -> 10 | G3: =Actividades!G3 -> 10 | H3: =D3*G3/100 -> 10
A4: 3 | B4: C. GESTION DE SEGURIDAD Y SALUD | C4: =Actividades!C4 -> 11 | D4: =Actividades!D4 -> 100 | E4: =Actividades!E4 -> 27.3 | F4: =Actividades!F4 -> 2.73 | G4: =Actividades!G4 -> 10 | H4: =D4*G4/100 -> 10
A5: 4 | B5: D. GESTION MEDIO AMBIENTE | C5: =Actividades!C5 -> 2 | D5: =Actividades!D5 -> 100 | E5: =Actividades!E5 -> 50 | F5: =Actividades!F5 -> 5 | G5: =Actividades!G5 -> 10 | H5: =D5*G5/100 -> 10
A6: 5 | B6: E. DOTACIONES DEL MANTENIMIENTO | C6: =[2]Actividades!C6 -> 7 | D6: =Actividades!D6 -> 100 | E6: =Actividades!E6 -> 28.6 | F6: =Actividades!F6 -> 2.86 | G6: =Actividades!G6 -> 10 | H6: =D6*G6/100 -> 10
A7: 6 | B7: F. GESTION DE REPUESTOS Y MATERIALES | C7: =[2]Actividades!C7 -> 22 | D7: =Actividades!D7 -> 100 | E7: =Actividades!E7 -> 54 | F7: =Actividades!F7 -> 5.4 | G7: =Actividades!G7 -> 10 | H7: =D7*G7/100 -> 10
A8: 7 | B8: G. SERVICIOS AL PERSONAL | C8: =[2]Actividades!C8 -> 5 | D8: =Actividades!D8 -> 100 | E8: =Actividades!E8 -> 75 | F8: =Actividades!F8 -> 3.75 | G8: =Actividades!G8 -> 5 | H8: =D8*G8/100 -> 5
A9: 8 | B9: H. SERVICIOS DE APOYO Y EQUIPOS | C9: =[2]Actividades!C9 -> 8 | D9: =Actividades!D9 -> 100 | E9: =Actividades!E9 -> 10 | F9: =Actividades!F9 -> 1 | G9: =Actividades!G9 -> 10 | H9: =D9*G9/100 -> 10
A10: 9 | B10: I. GESTION DE PERSONAS | C10: =[2]Actividades!C10 -> 4 | D10: =Actividades!D10 -> 100 | E10: =Actividades!E10 -> 0 | F10: =Actividades!F10 -> 0 | G10: =Actividades!G10 -> 10 | H10: =D10*G10/100 -> 10
A11: 10 | B11: J. GESTION Y CONTROL DE LA EJECUCION DEL MANTENIMIENTO | C11: =[2]Actividades!C11 -> 8 | D11: =Actividades!D11 -> 100 | E11: =Actividades!E11 -> 0 | F11: =Actividades!F11 -> 0 | G11: =Actividades!G11 -> 10 | H11: =D11*G11/100 -> 10
A12: 11 | B12: K. GESTION CIERRE MANTENIMIENTO | C12: =[2]Actividades!C12 -> 12 | D12: =Actividades!D12 -> 100 | E12: =Actividades!E12 -> 0 | F12: =Actividades!F12 -> 0 | G12: =Actividades!G12 -> 5 | H12: =D12*G12/100 -> 5
B14: SUMA | C14: =SUM(C2:C12) -> 104 | D14: =SUM(D2:D12) -> 1100 | E14: =SUM(E2:E12) -> 402.5 | F14: =SUM(F2:F12) -> 36.5 | G14: =SUM(G2:G12) -> 100 | H14: =SUM(H2:H12) -> 100

Sheet MATRIZ REPUESTOS LUBRICACION
G1: MATRIZ DE REPUESTOS LUBRICACION.
F4: FAENA : | G4: PUERTO CMDIC GMT1401A
F5: EQUIPO APL : | G5: FILTROS PUERTO
B7: INICIO DEL MANTENIMIENTO | G7: 44819 | N7: Real | O7: Esperado a la fecha
B8: Area: | G8: Filtrado y Embarque | L8: =G17 -> REPUESTOS HIDRAULICOS | N8: =M17*0.5 -> 0 | O8: =P17*0.5 -> 0.5 | P8: n
B9: Revisado por: | F9: Armando Pizarro/ Pedro Perez | P9: n
B10: Jefe de Área | F10: Juan Marisio
B11: Equipo | F11: 310FL003 | G11: ='[3]MATRIZ REPUESTOS MECANICOS'!G11 -> MANTENCION SEMESTRAL FILTRO PRENSA
B12: Fecha de Hoy | F12: =TODAY() -> 46163 | G12: =TODAY() -> 46163
B13: SD | F13: =[4]!HAZOP[Codigo] -> #REF!
L14: Cumplimiento del Area | N14: =SUM(N8:N12) -> 0 | O14: =SUM(O8:O12) -> 0.5 | P14: n
B16: ID | C16: CODIGO | D16: Stock Bodega | E16: Cant. Req. | F16: SALDO STOCK | G16: REPUESTOS | H16: APLICA | I16: Pond | J16: Frec | K16: DeadLine | L16: Avance | M16: Avance Ponderado | N16: Observaciones | O16: Evidencia | P16: Esperado
B17: 1 | C17: CODIGO | D17: Stock Bodega | E17: Cant. Req. | F17: SALDO STOCK | G17: REPUESTOS HIDRAULICOS | H17: APLICA | I17: =SUM(I23:I30) -> 1 | J17: FREC | K17: DEAD LINE | L17: =AVERAGE(L23:L30) -> 0 | M17: =SUM(M23:M30) -> 0 | N17: OBSERVACIONES | O17: RQ: | P17: =SUM(P23:P30) -> 1
B18: 1.0.1 | C18: 55442 | D18: =IFERROR(VLOOKUP(C18,Tabla_APL[[STOCKCODE]:[TYPE]],3,FALSE),"") -> 6 | E18: =[5]Repuestos!F37 -> 1 | F18: =D18-E18 -> 5 | G18: FILTRO DE VENTILACION | H18: 0 | I18: =IF(H18=1,1/SUM(H$18:H$22),0) -> 0 | J18: 40 | K18: ='[3]MATRIZ REPUESTOS ELEC. INSTRU.'!$G$7-J18 -> 44779 | L18: 0 | M18: =I18*L18 -> 0 | P18: =(IF(K18<=TODAY(),1,0))*I18 -> 0
B19: 1.0.2 | C19: 16584 | D19: =IFERROR(VLOOKUP(C19,Tabla_APL[[STOCKCODE]:[TYPE]],3,FALSE),"") -> 6 | E19: =[5]Repuestos!F38 -> 5 | F19: =D19-E19 -> 1 | G19: FILTRO DESECHABLE FS06C | H19: 0 | I19: =IF(H19=1,1/SUM(H$18:H$22),0) -> 0 | J19: 40 | K19: ='[3]MATRIZ REPUESTOS ELEC. INSTRU.'!$G$7-J19 -> 44779 | L19: 0 | M19: =I19*L19 -> 0 | P19: =(IF(K19<=TODAY(),1,0))*I19 -> 0
B20: 1.0.3 | C20: 300798 | D20: =IFERROR(VLOOKUP(C20,Tabla_APL[[STOCKCODE]:[TYPE]],3,FALSE),"") -> 5 | E20: =[5]Repuestos!F39 -> 5 | F20: =D20-E20 -> 0 | G20: MANOMETRO PRESION 0-400 BAR | H20: 0 | I20: =IF(H20=1,1/SUM(H$18:H$22),0) -> 0 | J20: 40 | K20: ='[3]MATRIZ REPUESTOS ELEC. INSTRU.'!$G$7-J20 -> 44779 | L20: 0 | M20: =I20*L20 -> 0 | N20: SOLICITAR A FERRETERIA | P20: =(IF(K20<=TODAY(),1,0))*I20 -> 0
B21: 1.0.4 | C21: 300780 | D21: =IFERROR(VLOOKUP(C21,Tabla_APL[[STOCKCODE]:[TYPE]],3,FALSE),"") -> 15 | E21: =[5]Repuestos!F40 -> 5 | F21: =D21-E21 -> 10 | G21: MANOMETRO PRESION 0-60 BAR | H21: 1 | I21: =IF(H21=1,1/SUM(H$18:H$22),0) -> 1 | J21: 40 | K21: ='[3]MATRIZ REPUESTOS ELEC. INSTRU.'!$G$7-J21 -> 44779 | L21: 0 | M21: =I21*L21 -> 0 | N21: SOLICITAR A FERRETERIA | P21: =(IF(K21<=TODAY(),1,0))*I21 -> 1
B22: 1.0.5 | C22: 744049 | D22: =IFERROR(VLOOKUP(C22,Tabla_APL[[STOCKCODE]:[TYPE]],3,FALSE),"") -> 56 | E22: =[5]Repuestos!F41 -> 2 | F22: =D22-E22 -> 54 | G22: MINI LUBER MODEL 125CC | H22: 0 | I22: =IF(H22=1,1/SUM(H$18:H$22),0) -> 0 | J22: 40 | K22: ='[3]MATRIZ REPUESTOS ELEC. INSTRU.'!$G$7-J22 -> 44779 | L22: 0 | M22: =I22*L22 -> 0 | P22: =(IF(K22<=TODAY(),1,0))*I22 -> 0
B23: 1.0.7 | C23: 758539 | D23: =IFERROR(VLOOKUP(C23,Tabla_APL[[STOCKCODE]:[TYPE]],3,FALSE),"") -> 0 | E23: 4 | F23: =D23-E23 -> -4 | G23: PORTAFILTRO | H23: 0 | I23: =IF(H23=1,1/SUM(H$23:H$30),0) -> 0 | J23: 40 | K23: =$G$7-J23 -> 44779 | L23: 0 | M23: =I23*L23 -> 0 | P23: =(IF(K23<=TODAY(),1,0))*I23 -> 0
B24: 1.0.9 | C24: 395343 | D24: =IFERROR(VLOOKUP(C24,Tabla_APL[[STOCKCODE]:[TYPE]],3,FALSE),"") -> 0 | E24: 1 | F24: =D24-E24 -> -1 | G24: HYDRAULCI HOSE, 1014-20 BLOQUEADO PROCESO OBSOLETO 2012 | H24: 0 | I24: =IF(H24=1,1/SUM(H$23:H$30),0) -> 0 | J24: 40 | K24: =$G$7-J24 -> 44779 | L24: 0 | M24: =I24*L24 -> 0 | P24: =(IF(K24<=TODAY(),1,0))*I24 -> 0
B25: 1.0.10 | C25: 395350 | D25: =IFERROR(VLOOKUP(C25,Tabla_APL[[STOCKCODE]:[TYPE]],3,FALSE),"") -> 0 | E25: 1 | F25: =D25-E25 -> -1 | G25: HYDRAULCI HOSE, 1014-20 BLOQUEADO PROCESO OBSOLETO 2012 | H25: 0 | I25: =IF(H25=1,1/SUM(H$23:H$30),0) -> 0 | J25: 40 | K25: =$G$7-J25 -> 44779 | L25: 0 | M25: =I25*L25 -> 0 | P25: =(IF(K25<=TODAY(),1,0))*I25 -> 0
B26: 1.0.11 | C26: 395368 | D26: =IFERROR(VLOOKUP(C26,Tabla_APL[[STOCKCODE]:[TYPE]],3,FALSE),"") -> 0 | E26: 1 | F26: =D26-E26 -> -1 | G26: HYDRAULCI HOSE, 720-08 BLOQUEADO PROCESO OBSOLETO 2012 | H26: 0 | I26: =IF(H26=1,1/SUM(H$23:H$30),0) -> 0 | J26: 40 | K26: =$G$7-J26 -> 44779 | L26: 0 | M26: =I26*L26 -> 0 | P26: =(IF(K26<=TODAY(),1,0))*I26 -> 0
B27: 1.0.12 | C27: 395376 | D27: =IFERROR(VLOOKUP(C27,Tabla_APL[[STOCKCODE]:[TYPE]],3,FALSE),"") -> 0 | E27: 1 | F27: =D27-E27 -> -1 | G27: HYDRAULCI HOSE, 720-08 BLOQUEADO PROCESO OBSOLETO 2012 | H27: 0 | I27: =IF(H27=1,1/SUM(H$23:H$30),0) -> 0 | J27: 40 | K27: =$G$7-J27 -> 44779 | L27: 0 | M27: =I27*L27 -> 0 | P27: =(IF(K27<=TODAY(),1,0))*I27 -> 0
B28: 1.0.13 | C28: 395384 | D28: =IFERROR(VLOOKUP(C28,Tabla_APL[[STOCKCODE]:[TYPE]],3,FALSE),"") -> 0 | E28: 1 | F28: =D28-E28 -> -1 | G28: HYDRAULCI HOSE, 720-08 BLOQUEADO PROCESO OBSOLETO 2012 | H28: 0 | I28: =IF(H28=1,1/SUM(H$23:H$30),0) -> 0 | J28: 40 | K28: =$G$7-J28 -> 44779 | L28: 0 | M28: =I28*L28 -> 0 | P28: =(IF(K28<=TODAY(),1,0))*I28 -> 0
B29: 1.0.14 | C29: 128603 | D29: =IFERROR(VLOOKUP(C29,Tabla_APL[[STOCKCODE]:[TYPE]],3,FALSE),"") -> 1 | E29: 1 | F29: =D29-E29 -> 0 | G29: Código Ferreteria CS 000747913 | H29: 1 | I29: =IF(H29=1,1/SUM(H$23:H$30),0) -> 0.5 | J29: 40 | K29: =$G$7-J29 -> 44779 | L29: 0 | M29: =I29*L29 -> 0 | P29: =(IF(K29<=TODAY(),1,0))*I29 -> 0.5
B30: 1.0.16 | C30: 166801 | D30: =IFERROR(VLOOKUP(C30,Tabla_APL[[STOCKCODE]:[TYPE]],3,FALSE),"") -> 34 | E30: 6 | F30: =D30-E30 -> 28 | G30: LUBRICADOR AUTOMATICO 150 GRS | H30: 1 | I30: =IF(H30=1,1/SUM(H$23:H$30),0) -> 0.5 | J30: 40 | K30: =$G$7-J30 -> 44779 | L30: 0 | M30: =I30*L30 -> 0 | P30: =(IF(K30<=TODAY(),1,0))*I30 -> 0.5
B31: 1.0.20 | C31: 657148 | D31: =IFERROR(VLOOKUP(C31,Tabla_APL[[STOCKCODE]:[TYPE]],3,FALSE),"") -> 0 | E31: 4 | F31: =D31-E31 -> -4 | G31: Mobil SHC 632 | H31: 3 | I31: =IF(H31=1,1/SUM(H$23:H$30),0) -> 0 | J31: 42 | K31: =$G$7-J31 -> 44777 | L31: 0 | M31: =I31*L31 -> 0 | N31: CUANDO HAY CAMBIO DE ACEITE SOLICITAR 4 | P31: =(IF(K31<=TODAY(),1,0))*I31 -> 0
B32: 1.0.6 | C32: 73700 | D32: =IFERROR(VLOOKUP(C32,Tabla_APL[[STOCKCODE]:[TYPE]],3,FALSE),"") -> 2 | E32: 0 | F32: =D32-E32 -> 2 | G32: BOMBA ALTA PRESION | H32: 0 | I32: =IF(H32=1,1/SUM(H$23:H$30),0) -> 0 | J32: 40 | K32: =$G$7-J32 -> 44779 | L32: 0 | M32: =I32*L32 -> 0 | P32: =(IF(K32<=TODAY(),1,0))*I32 -> 0
C33: 537746 | G33: FILTRO RESPIRADERO SILICA GEL

Sheet Matriz Rep. Mec.
G1: MATRIZ DE REPUESTOS Y INSUMES MECÁNICOS
F4: FAENA : | G4: PUERTO CMDIC GMT1401A
F5: EQUIPO APL : | G5: FILTROS PUERTO
B7: INICIO DEL MANTENIMIENTO | G7: =HAZOP[FechaVencimiento]-13 -> 44021 | N7: Real | O7: Esperado a la fecha
B8: Area: | G8: Filtrado y Embarque | L8: =G16 -> REPUESTOS MECÁNICOS | N8: =((M17+M30+M54+M73+M88+M93+M102+M110+M116+M135)/10)*0.2 -> 0.054190476 | O8: =((P17+P30+P54+P73+P88+P93+P102+P110+P116+P135)/10)*0.2 -> 0.19492063 | P8: n
B9: Revisado por: | F9: Armando Pizarro/ Pedro Perez | L9: =G165 -> HERRAMIENTAS | N9: =M165*0.2 -> 0 | O9: =P165*0.2 -> 0.2 | P9: n
B10: Jefe de Área | F10: Juan Marisio | L10: =G197 -> INSTRUMENTO Y EQUIPO | N10: =M197*0.2 -> 0 | O10: =P197*0.2 -> 0.2 | P10: n
B11: Equipo | F11: 310FL003 | G11: 310FL00X | L11: =G217 -> MATERIALES GENERALES | N11: =M217*0.2 -> 0 | O11: =P217*0.2 -> 0.2 | P11: n
B12: Fecha de Hoy | F12: =TODAY() -> 46163 | G12: =TODAY() -> 46163 | L12: =G229 -> EPP | N12: =M229*0.2 -> 0 | O12: =P229*0.2 -> 0.2 | P12: n
B13: SD | F13: =[1]!HAZOP[Codigo] -> #REF! | G13: =HAZOP[Codigo] -> SD 2187
L14: Cumplimiento del Area | N14: =SUM(N8:N12) -> 0.054190476 | O14: =SUM(O8:O12) -> 0.99492063 | P14: n
B16: ID | C16: CODIGO | D16: Stock Bodega | E16: Cant. Req. | F16: SALDO STOCK | G16: REPUESTOS MECÁNICOS | H16: APLICA | I16: Pond | J16: Frec | K16: DeadLine | L16: Avance | M16: Avance Ponderado | N16: Observaciones | O16: Evidencia | P16: Esperado
B17: 1 | C17: CODIGO | D17: Stock Bodega | E17: Cant. Req. | F17: SALDO STOCK | G17: LINEA AIRE MEMBRANA | H17: APLICA | I17: =SUM(I18:I29) -> 1 | J17: FREC | K17: DEAD LINE | L17: =AVERAGE(L18:L29) -> 0.3 | M17: =SUM(M18:M29) -> 0.3 | N17: OBSERVACIONES | O17: RQ: | P17: =SUM(P18:P29) -> 1
B18: 1.0.1 | C18: 746231 | D18: =IFERROR(VLOOKUP(C18,Tabla_APL[[STOCKCODE]:[TYPE]],3,FALSE),"") -> 4 | E18: 1 | F18: =D18-E18 -> 3 | G18: CAÑERIA CON BRIDAS (CABEZAL FIJO) | H18: 1 | I18: =IF(H18=1,1/SUM(H$18:H$29),0) -> 0.083333333 | J18: 40 | K18: =$G$7-J18 -> 43981 | L18: 0.3 | M18: =I18*L18 -> 0.025 | N18: SE GENERA RQ CON 95 ITEM | O18: A64881 | P18: =(IF(K18<=TODAY(),1,0))*I18 -> 0.083333333
B19: 1.0.2 | C19: 746218 | D19: =IFERROR(VLOOKUP(C19,Tabla_APL[[STOCKCODE]:[TYPE]],3,FALSE),"") -> 4 | E19: 1 | F19: =D19-E19 -> 3 | G19: CAÑERIA CON BRIDAS (CUELLO CISNE) | H19: 1 | I19: =IF(H19=1,1/SUM(H$18:H$29),0) -> 0.083333333 | J19: 40 | K19: =$G$7-J19 -> 43981 | L19: 0.3 | M19: =I19*L19 -> 0.025 | P19: =(IF(K19<=TODAY(),1,0))*I19 -> 0.083333333
B20: 1.0.3 | C20: 746232 | D20: =IFERROR(VLOOKUP(C20,Tabla_APL[[STOCKCODE]:[TYPE]],3,FALSE),"") -> 8 | E20: 1 | F20: =D20-E20 -> 7 | G20: CAÑERIA CON BRIDAS (FLAUTA) | H20: 1 | I20: =IF(H20=1,1/SUM(H$18:H$29),0) -> 0.083333333 | J20: 40 | K20: =$G$7-J20 -> 43981 | L20: 0.3 | M20: =I20*L20 -> 0.025 | P20: =(IF(K20<=TODAY(),1,0))*I20 -> 0.083333333
B21: 1.0.4 | C21: 123216 | D21: =IFERROR(VLOOKUP(C21,Tabla_APL[[STOCKCODE]:[TYPE]],3,FALSE),"") -> 16 | E21: 1 | F21: =D21-E21 -> 15 | G21: VALVULA RETENCION (NO REPARABLE J. T.) | H21: 1 | I21: =IF(H21=1,1/SUM(H$18:H$29),0) -> 0.083333333 | J21: 40 | K21: =$G$7-J21 -> 43981 | L21: 0.3 | M21: =I21*L21 -> 0.025 | P21: =(IF(K21<=TODAY(),1,0))*I21 -> 0.083333333
B22: 1.0.5 | C22: 88948 | D22: =IFERROR(VLOOKUP(C22,Tabla_APL[[STOCKCODE]:[TYPE]],3,FALSE),"") -> 47 | E22: 1 | F22: =D22-E22 -> 46 | G22: VALVULA CHECK | H22: 1 | I22: =IF(H22=1,1/SUM(H$18:H$29),0) -> 0.083333333 | J22: 40 | K22: =$G$7-J22 -> 43981 | L22: 0.3 | M22: =I22*L22 -> 0.025 | P22: =(IF(K22<=TODAY(),1,0))*I22 -> 0.083333333
B23: 1.0.6 | C23: 123224 | D23: =IFERROR(VLOOKUP(C23,Tabla_APL[[STOCKCODE]:[TYPE]],3,FALSE),"") -> 28 | E23: 2 | F23: =D23-E23 -> 26 | G23: JUNTA EXPANSION 2" ANSI 150 LBS | H23: 1 | I23: =IF(H23=1,1/SUM(H$18:H$29),0) -> 0.083333333 | J23: 40 | K23: =$G$7-J23 -> 43981 | L23: 0.3 | M23: =I23*L23 -> 0.025 | P23: =(IF(K23<=TODAY(),1,0))*I23 -> 0.083333333
B24: 1.0.7 | C24: 114330 | D24: 28 | E24: 2 | F24: =D24-E24 -> 26 | G24: VALVULA V7 / V10/070-120 DN50/PN V10 | H24: 1 | I24: =IF(H24=1,1/SUM(H$18:H$29),0) -> 0.083333333 | J24: 40 | K24: =$G$7-J24 -> 43981 | L24: 0.3 | M24: =I24*L24 -> 0.025 | P24: =(IF(K24<=TODAY(),1,0))*I24 -> 0.083333333
B25: 1.0.8 | C25: 746233 | D25: =IFERROR(VLOOKUP(C25,Tabla_APL[[STOCKCODE]:[TYPE]],3,FALSE),"") -> 10 | E25: 2 | F25: =D25-E25 -> 8 | G25: CAÑERIA CON BRIDAS(top blow) | H25: 1 | I25: =IF(H25=1,1/SUM(H$18:H$29),0) -> 0.083333333 | J25: 40 | K25: =$G$7-J25 -> 43981 | L25: 0.3 | M25: =I25*L25 -> 0.025 | P25: =(IF(K25<=TODAY(),1,0))*I25 -> 0.083333333
B26: 1.0.9 | C26: 448068 | D26: =IFERROR(VLOOKUP(C26,Tabla_APL[[STOCKCODE]:[TYPE]],3,FALSE),"") -> 11 | E26: 1 | F26: =D26-E26 -> 10 | G26: VALVULA REGULADORA DE PRESION | H26: 1 | I26: =IF(H26=1,1/SUM(H$18:H$29),0) -> 0.083333333 | J26: 40 | K26: =$G$7-J26 -> 43981 | L26: 0.3 | M26: =I26*L26 -> 0.025 | P26: =(IF(K26<=TODAY(),1,0))*I26 -> 0.083333333
B27: 1.0.10 | C27: 746234 | D27: =IFERROR(VLOOKUP(C27,Tabla_APL[[STOCKCODE]:[TYPE]],3,FALSE),"") -> 5 | E27: 1 | F27: =D27-E27 -> 4 | G27: CAÑERIA CON BRIDAS | H27: 1 | I27: =IF(H27=1,1/SUM(H$18:H$29),0) -> 0.083333333 | J27: 40 | K27: =$G$7-J27 -> 43981 | L27: 0.3 | M27: =I27*L27 -> 0.025 | P27: =(IF(K27<=TODAY(),1,0))*I27 -> 0.083333333
B28: 1.0.11 | C28: 155762 | D28: =IFERROR(VLOOKUP(C28,Tabla_APL[[STOCKCODE]:[TYPE]],3,FALSE),"") -> 21 | E28: 1 | F28: =D28-E28 -> 20 | G28: VALVULA DN 50/PN10 (VV manual) | H28: 1 | I28: =IF(H28=1,1/SUM(H$18:H$29),0) -> 0.083333333 | J28: 40 | K28: =$G$7-J28 -> 43981 | L28: 0.3 | M28: =I28*L28 -> 0.025 | P28: =(IF(K28<=TODAY(),1,0))*I28 -> 0.083333333
B29: 1.0.12 | C29: 746235 | D29: =IFERROR(VLOOKUP(C29,Tabla_APL[[STOCKCODE]:[TYPE]],3,FALSE),"") -> 4 | E29: 1 | F29: =D29-E29 -> 3 | G29: CAÑERIA BRIDAS | H29: 1 | I29: =IF(H29=1,1/SUM(H$18:H$29),0) -> 0.083333333 | J29: 40 | K29: =$G$7-J29 -> 43981 | L29: 0.3 | M29: =I29*L29 -> 0.025 | P29: =(IF(K29<=TODAY(),1,0))*I29 -> 0.083333333
B30: 1.1 | C30: CODIGO | D30: Stock Bodega | E30: Cant. Req. | F30: EXISTENCIA | G30: LINEA SOPLADO SUPERIOR | H30: APLICA | I30: =SUM(I31:I53) -> 1 | J30: FREC | K30: DEAD LINE | L30: =AVERAGE(L31:L53) -> 0.3 | M30: =SUM(M31:M53) -> 0.3 | N30: OBSERVACIONES | O30: RQ: | P30: =SUM(P31:P53) -> 1
B31: 1.1.1 | C31: 123224 | D31: =IFERROR(VLOOKUP(C31,Tabla_APL[[STOCKCODE]:[TYPE]],3,FALSE),"") -> 28 | E31: 2 | F31: =D31-E31 -> 26 | G31: JUNTA EXPANSION 2" ANSI 150 LBS | H31: 1 | I31: =IF(H31=1,1/SUM(H$31:H$53),0) -> 0.045454545 | J31: 40 | K31: =$G$7-J31 -> 43981 | L31: 0.3 | M31: =I31*L31 -> 0.013636364 | P31: =(IF(K31<=TODAY(),1,0))*I31 -> 0.045454545
B32: 1.1.2 | C32: 746221 | D32: =IFERROR(VLOOKUP(C32,Tabla_APL[[STOCKCODE]:[TYPE]],3,FALSE),"") -> 10 | E32: 2 | F32: =D32-E32 -> 8 | G32: CAÑERIA CON BRIDAS | H32: 1 | I32: =IF(H32=1,1/SUM(H$31:H$53),0) -> 0.045454545 | J32: 40 | K32: =$G$7-J32 -> 43981 | L32: 0.3 | M32: =I32*L32 -> 0.013636364 | P32: =(IF(K32<=TODAY(),1,0))*I32 -> 0.045454545
B33: 1.1.3 | C33: 155762 | D33: =IFERROR(VLOOKUP(C33,Tabla_APL[[STOCKCODE]:[TYPE]],3,FALSE),"") -> 21 | E33: 2 | F33: =D33-E33 -> 19 | G33: VALVULA DN 50/PN10 (VV manual) | H33: 1 | I33: =IF(H33=1,1/SUM(H$31:H$53),0) -> 0.045454545 | J33: 40 | K33: =$G$7-J33 -> 43981 | L33: 0.3 | M33: =I33*L33 -> 0.013636364 | P33: =(IF(K33<=TODAY(),1,0))*I33 -> 0.045454545
B34: 1.1.4 | C34: 746222 | D34: =IFERROR(VLOOKUP(C34,Tabla_APL[[STOCKCODE]:[TYPE]],3,FALSE),"") -> 6 | E34: 1 | F34: =D34-E34 -> 5 | G34: CAÑERIA CON BRIDAS | H34: 1 | I34: =IF(H34=1,1/SUM(H$31:H$53),0) -> 0.045454545 | J34: 40 | K34: =$G$7-J34 -> 43981 | L34: 0.3 | M34: =I34*L34 -> 0.013636364 | P34: =(IF(K34<=TODAY(),1,0))*I34 -> 0.045454545
B35: 1.1.5 | C35: 746225 | D35: =IFERROR(VLOOKUP(C35,Tabla_APL[[STOCKCODE]:[TYPE]],3,FALSE),"") -> 10 | E35: 2 | F35: =D35-E35 -> 8 | G35: CAÑERIA CON BRIDAS | H35: 1 | I35: =IF(H35=1,1/SUM(H$31:H$53),0) -> 0.045454545 | J35: 40 | K35: =$G$7-J35 -> 43981 | L35: 0.3 | M35: =I35*L35 -> 0.013636364 | P35: =(IF(K35<=TODAY(),1,0))*I35 -> 0.045454545
B36: 1.1.6 | C36: 448068 | D36: =IFERROR(VLOOKUP(C36,Tabla_APL[[STOCKCODE]:[TYPE]],3,FALSE),"") -> 11 | E36: 1 | F36: =D36-E36 -> 10 | G36: VALVULA REGULADORA DE PRESION | H36: 1 | I36: =IF(H36=1,1/SUM(H$31:H$53),0) -> 0.045454545 | J36: 40 | K36: =$G$7-J36 -> 43981 | L36: 0.3 | M36: =I36*L36 -> 0.013636364 | P36: =(IF(K36<=TODAY(),1,0))*I36 -> 0.045454545
B37: 1.1.7 | C37: 155903 | D37: =IFERROR(VLOOKUP(C37,Tabla_APL[[STOCKCODE]:[TYPE]],3,FALSE),"") -> 8 | E37: 2 | F37: =D37-E37 -> 6 | G37: VALVULA DN50/PN16, RS-50/050-100 V6-V8 | H37: 1 | I37: =IF(H37=1,1/SUM(H$31:H$53),0) -> 0.045454545 | J37: 40 | K37: =$G$7-J37 -> 43981 | L37: 0.3 | M37: =I37*L37 -> 0.013636364 | P37: =(IF(K37<=TODAY(),1,0))*I37 -> 0.045454545
B38: 1.1.8 | C38: 6965 | D38: =IFERROR(VLOOKUP(C38,Tabla_APL[[STOCKCODE]:[TYPE]],3,FALSE),"") -> 78 | E38: 2 | F38: =D38-E38 -> 76 | G38: MANOMETRO; MANOMETRO 2-1/2"DIAL 0-200 PSI 1/4" NPT | H38: 1 | I38: =IF(H38=1,1/SUM(H$31:H$53),0) -> 0.045454545 | J38: 40 | K38: =$G$7-J38 -> 43981 | L38: 0.3 | M38: =I38*L38 -> 0.013636364 | P38: =(IF(K38<=TODAY(),1,0))*I38 -> 0.045454545
B39: 1.1.9 | C39: 155937 | D39: =IFERROR(VLOOKUP(C39,Tabla_APL[[STOCKCODE]:[TYPE]],3,FALSE),"") -> 10 | E39: 2 | F39: =D39-E39 -> 8 | G39: CAÑERIA CON BRIDAS | H39: 1 | I39: =IF(H39=1,1/SUM(H$31:H$53),0) -> 0.045454545 | J39: 40 | K39: =$G$7-J39 -> 43981 | L39: 0.3 | M39: =I39*L39 -> 0.013636364 | P39: =(IF(K39<=TODAY(),1,0))*I39 -> 0.045454545
B40: 1.1.15 | C40: 746224 | D40: =IFERROR(VLOOKUP(C40,Tabla_APL[[STOCKCODE]:[TYPE]],3,FALSE),"") -> 4 | E40: 1 | F40: =D40-E40 -> 3 | G40: DUCTO AIRE (2" cabezal movil) | H40: 1 | I40: =IF(H40=1,1/SUM(H$31:H$53),0) -> 0.045454545 | J40: 40 | K40: =$G$7-J40 -> 43981 | L40: 0.3 | M40: =I40*L40 -> 0.013636364 | P40: =(IF(K40<=TODAY(),1,0))*I40 -> 0.045454545
C41: 155762 | D41: =IFERROR(VLOOKUP(C41,Tabla_APL[[STOCKCODE]:[TYPE]],3,FALSE),"") -> 21 | G41: ´valvula mariposa 2"
B42: 1.1.16 | C42: 155853 | D42: =IFERROR(VLOOKUP(C42,Tabla_APL[[STOCKCODE]:[TYPE]],3,FALSE),"") -> 8 | E42: 2 | F42: =D42-E42 -> 6 | G42: ACOPLAMIENTO TUBO 2" | H42: 1 | I42: =IF(H42=1,1/SUM(H$31:H$53),0) -> 0.045454545 | J42: 40 | K42: =$G$7-J42 -> 43981 | L42: 0.3 | M42: =I42*L42 -> 0.013636364 | P42: =(IF(K42<=TODAY(),1,0))*I42 -> 0.045454545
B43: 1.1.17 | C43: 155861 | D43: =IFERROR(VLOOKUP(C43,Tabla_APL[[STOCKCODE]:[TYPE]],3,FALSE),"") -> 24 | E43: 2 | F43: =D43-E43 -> 22 | G43: ACOPLAMIENTO DE CAÑERIA RACOR DN50 (punta milano 2") | H43: 1 | I43: =IF(H43=1,1/SUM(H$31:H$53),0) -> 0.045454545 | J43: 40 | K43: =$G$7-J43 -> 43981 | L43: 0.3 | M43: =I43*L43 -> 0.013636364 | P43: =(IF(K43<=TODAY(),1,0))*I43 -> 0.045454545
B44: 1.1.18 | C44: 158147 | D44: =IFERROR(VLOOKUP(C44,Tabla_APL[[STOCKCODE]:[TYPE]],3,FALSE),"") -> 114 | E44: 17 | F44: =D44-E44 -> 97 | G44: ABRAZADERA SIN FIN 3" | H44: 1 | I44: =IF(H44=1,1/SUM(H$31:H$53),0) -> 0.045454545 | J44: 40 | K44: =$G$7-J44 -> 43981 | L44: 0.3 | M44: =I44*L44 -> 0.013636364 | P44: =(IF(K44<=TODAY(),1,0))*I44 -> 0.045454545
...

Sheet MATRIZ REPUESTOS ELEC. INSTRU.
G1: MATRIZ DE REPUESTOS Y INSUMES HIDRAULICOS Y ELECTRICOS
F4: FAENA : | G4: PUERTO CMDIC GMT1401A
F5: EQUIPO APL : | G5: FILTROS PUERTO
B7: INICIO DEL MANTENIMIENTO | G7: 44819 | N7: Real | O7: Esperado a la fecha
B8: Area: | G8: Filtrado y Embarque | L8: =G17 -> REPUESTOS ELECTRICOS | N8: =M17*0.5 -> 0.24 | O8: =P17*0.5 -> 0.5 | P8: n
B9: Revisado por: | F9: Armando Pizarro/ Pedro Perez | L9: =G40 -> REPUESTOS ELECTRICOS FEEDER FILTROS | N9: =M40*0.5 -> 0 | O9: =P17*0.5 -> 0.5 | P9: n
B10: Jefe de Área | F10: Juan Marisio
B11: Equipo | F11: 310FL003 | G11: ='[3]MATRIZ REPUESTOS MECANICOS'!G11 -> MANTENCION SEMESTRAL FILTRO PRENSA
B12: Fecha de Hoy | F12: =TODAY() -> 46163 | G12: =TODAY() -> 46163
B13: SD | F13: =[4]!HAZOP[Codigo] -> #REF!
L14: Cumplimiento del Area | N14: =SUM(N8:N12) -> 0.24 | O14: =SUM(O8:O12) -> 1 | P14: n
B16: ID | C16: CODIGO | D16: Stock Bodega | E16: Cant. Req. | F16: SALDO STOCK | G16: REPUESTOS | H16: APLICA | I16: Pond | J16: Frec | K16: DeadLine | L16: Avance | M16: Avance Ponderado | N16: Observaciones | O16: Evidencia | P16: Esperado
B17: 1.1 | C17: CODIGO | D17: Stock Bodega | E17: Cant. Req. | F17: EXISTENCIA | G17: REPUESTOS ELECTRICOS | H17: APLICA | I17: =SUM(I18:I39) -> 1 | J17: FREC | K17: DEAD LINE | L17: =AVERAGE(L18:L39) -> 0.10909091 | M17: =SUM(M18:M39) -> 0.48 | N17: OBSERVACIONES | O17: RQ: | P17: =SUM(P18:P39) -> 1
B18: 1.1.1 | C18: 401315 | D18: =IFERROR(VLOOKUP(C18,Tabla_APL[[STOCKCODE]:[TYPE]],3,FALSE),"") -> 7 | E18: 4 | F18: =D18-E18 -> 3 | G18: PULLCORD | H18: 0 | I18: =IF(H18=1,1/SUM(H$18:H$39),0) -> 0 | J18: 40 | K18: =$G$7-J18 -> 44779 | L18: 0 | M18: =I18*L18 -> 0 | P18: =(IF(K18<=TODAY(),1,0))*I18 -> 0
B19: 1.1.2 | C19: 743701 | D19: =IFERROR(VLOOKUP(C19,Tabla_APL[[STOCKCODE]:[TYPE]],3,FALSE),"") -> 10 | E19: 10 | F19: =D19-E19 -> 0 | G19: ELECTROVALVULA SIMPLE EFECTO (TABLERO NEUMATICO PLANTA FILTRADO) | H19: 0 | I19: =IF(H19=1,1/SUM(H$18:H$39),0) -> 0 | J19: 40 | K19: =$G$7-J19 -> 44779 | L19: 0 | M19: =I19*L19 -> 0 | P19: =(IF(K19<=TODAY(),1,0))*I19 -> 0
B20: 1.1.3 | C20: 358283 | D20: =IFERROR(VLOOKUP(C20,Tabla_APL[[STOCKCODE]:[TYPE]],3,FALSE),"") -> 8 | E20: 4 | F20: =D20-E20 -> 4 | G20: CELDA DE CARGA | H20: 0 | I20: =IF(H20=1,1/SUM(H$18:H$39),0) -> 0 | J20: 40 | K20: =$G$7-J20 -> 44779 | L20: 0 | M20: =I20*L20 -> 0 | P20: =(IF(K20<=TODAY(),1,0))*I20 -> 0
B21: 1.1.4 | C21: 127704 | D21: =IFERROR(VLOOKUP(C21,Tabla_APL[[STOCKCODE]:[TYPE]],3,FALSE),"") -> 41 | E21: 9 | F21: =D21-E21 -> 32 | G21: RELE CONTROL SALIDA 24 VDC | H21: 0 | I21: =IF(H21=1,1/SUM(H$18:H$39),0) -> 0 | J21: 40 | K21: =$G$7-J21 -> 44779 | L21: 0 | M21: =I21*L21 -> 0 | P21: =(IF(K21<=TODAY(),1,0))*I21 -> 0
B22: 1.1.5 | C22: 453944 | D22: =IFERROR(VLOOKUP(C22,Tabla_APL[[STOCKCODE]:[TYPE]],3,FALSE),"") -> 2 | E22: 1 | F22: =D22-E22 -> 1 | G22: UNIDAD FILTRO REGULADOR LUBRICADOR C/ MANOMETRO 3/8" | H22: 0 | I22: =IF(H22=1,1/SUM(H$18:H$39),0) -> 0 | J22: 40 | K22: =$G$7-J22 -> 44779 | L22: 0 | M22: =I22*L22 -> 0 | P22: =(IF(K22<=TODAY(),1,0))*I22 -> 0
B23: 1.1.6 | C23: 453951 | D23: =IFERROR(VLOOKUP(C23,Tabla_APL[[STOCKCODE]:[TYPE]],3,FALSE),"") -> 9 | E23: 1 | F23: =D23-E23 -> 8 | G23: UNIDAD FILTRO REGULADOR LUBRICADOR C/ MANOMETRO 1/2" | H23: 0 | I23: =IF(H23=1,1/SUM(H$18:H$39),0) -> 0 | J23: 40 | K23: =$G$7-J23 -> 44779 | L23: 0 | M23: =I23*L23 -> 0 | P23: =(IF(K23<=TODAY(),1,0))*I23 -> 0
B24: 1.1.7 | C24: 449686 | D24: =IFERROR(VLOOKUP(C24,Tabla_APL[[STOCKCODE]:[TYPE]],3,FALSE),"") -> 0 | E24: 4 | F24: =D24-E24 -> -4 | G24: VALVULA DE CORTE 1/2" | H24: 0 | I24: =IF(H24=1,1/SUM(H$18:H$39),0) -> 0 | J24: 40 | K24: =$G$7-J24 -> 44779 | L24: 0 | M24: =I24*L24 -> 0 | P24: =(IF(K24<=TODAY(),1,0))*I24 -> 0
B25: 1.1.8 | C25: 741009 | D25: =IFERROR(VLOOKUP(C25,Tabla_APL[[STOCKCODE]:[TYPE]],3,FALSE),"") -> 1 | E25: 4 | F25: =D25-E25 -> -3 | G25: CONTACTOR LC1-D50F7 BOBINA 110VAC 22KW | H25: 1 | I25: =IF(H25=1,1/SUM(H$18:H$39),0) -> 0.2 | J25: 40 | K25: =$G$7-J25 -> 44779 | L25: 0.8 | M25: =I25*L25 -> 0.16 | P25: =(IF(K25<=TODAY(),1,0))*I25 -> 0.2
B26: 1.1.9 | C26: 426965 | D26: =IFERROR(VLOOKUP(C26,Tabla_APL[[STOCKCODE]:[TYPE]],3,FALSE),"") -> 38 | E26: 4 | F26: =D26-E26 -> 34 | G26: SENSOR DESALINEAMIENTO FILTRO | H26: 0 | I26: =IF(H26=1,1/SUM(H$18:H$39),0) -> 0 | J26: 40 | K26: =$G$7-J26 -> 44779 | L26: 0 | M26: =I26*L26 -> 0 | P26: =(IF(K26<=TODAY(),1,0))*I26 -> 0
B27: 1.1.10 | C27: 409243 | D27: =IFERROR(VLOOKUP(C27,Tabla_APL[[STOCKCODE]:[TYPE]],3,FALSE),"") -> 6 | E27: =[5]Repuestos!F18 -> 3 | F27: =D27-E27 -> 3 | G27: SWITCH DE PRESION UNIDAD HIDRAULICA (Filtro 4 y 5) | H27: 0 | I27: =IF(H27=1,1/SUM(H$18:H$39),0) -> 0 | J27: 40 | K27: =$G$7-J27 -> 44779 | L27: 0 | M27: =I27*L27 -> 0 | P27: =(IF(K27<=TODAY(),1,0))*I27 -> 0
B28: 1.1.11 | C28: 504423 | D28: =IFERROR(VLOOKUP(C28,Tabla_APL[[STOCKCODE]:[TYPE]],3,FALSE),"") -> 152 | E28: =[5]Repuestos!F19 -> 4 | F28: =D28-E28 -> 148 | G28: CONECTOR ;CONECTOR RECTO 3/8 X 1/4" NPT | H28: 0 | I28: =IF(H28=1,1/SUM(H$18:H$39),0) -> 0 | J28: 40 | K28: =$G$7-J28 -> 44779 | L28: 0 | M28: =I28*L28 -> 0 | P28: =(IF(K28<=TODAY(),1,0))*I28 -> 0
B29: 1.1.12 | C29: 127639 | D29: =IFERROR(VLOOKUP(C29,Tabla_APL[[STOCKCODE]:[TYPE]],3,FALSE),"") -> 4 | E29: =[5]Repuestos!F20 -> 1 | F29: =D29-E29 -> 3 | G29: SAFETY SWITCH MOTOVIBRADOR | H29: 0 | I29: =IF(H29=1,1/SUM(H$18:H$39),0) -> 0 | J29: 40 | K29: =$G$7-J29 -> 44779 | L29: 0 | M29: =I29*L29 -> 0 | P29: =(IF(K29<=TODAY(),1,0))*I29 -> 0
B30: 1.1.13 | C30: 407569 | D30: =IFERROR(VLOOKUP(C30,Tabla_APL[[STOCKCODE]:[TYPE]],3,FALSE),"") -> 2 | E30: =[5]Repuestos!F21 -> 1 | F30: =D30-E30 -> 1 | G30: INTERRUPTOR DE SEGURIDAD BBA ALTA | H30: 1 | I30: =IF(H30=1,1/SUM(H$18:H$39),0) -> 0.2 | J30: 40 | K30: =$G$7-J30 -> 44779 | L30: 0.8 | M30: =I30*L30 -> 0.16 | P30: =(IF(K30<=TODAY(),1,0))*I30 -> 0.2
B31: 1.1.14 | C31: 159368 | D31: =IFERROR(VLOOKUP(C31,Tabla_APL[[STOCKCODE]:[TYPE]],3,FALSE),"") -> 4 | E31: =[5]Repuestos!F22 -> 4 | F31: =D31-E31 -> 0 | G31: CONTACTOR MOTOVIBRADOR | H31: 1 | I31: =IF(H31=1,1/SUM(H$18:H$39),0) -> 0.2 | J31: 40 | K31: =$G$7-J31 -> 44779 | L31: 0.8 | M31: =I31*L31 -> 0.16 | P31: =(IF(K31<=TODAY(),1,0))*I31 -> 0.2
B32: 1.1.15 | C32: 6833 | D32: =IFERROR(VLOOKUP(C32,Tabla_APL[[STOCKCODE]:[TYPE]],3,FALSE),"") -> 16 | E32: =[5]Repuestos!F23 -> 1 | F32: =D32-E32 -> 15 | G32: MANOMETRO 2" DIAL 0-160 PSI 1 | H32: 0 | I32: =IF(H32=1,1/SUM(H$18:H$39),0) -> 0 | J32: 40 | K32: =$G$7-J32 -> 44779 | L32: 0 | M32: =I32*L32 -> 0 | P32: =(IF(K32<=TODAY(),1,0))*I32 -> 0
B33: 1.1.16 | C33: 177899 | D33: =IFERROR(VLOOKUP(C33,Tabla_APL[[STOCKCODE]:[TYPE]],3,FALSE),"") -> 2563 | E33: =[5]Repuestos!F24 -> 1 | F33: =D33-E33 -> 2562 | G33: PIOLA DE PULL CORD | H33: 1 | I33: =IF(H33=1,1/SUM(H$18:H$39),0) -> 0.2 | J33: 40 | K33: =$G$7-J33 -> 44779 | L33: 0 | M33: =I33*L33 -> 0 | P33: =(IF(K33<=TODAY(),1,0))*I33 -> 0.2
B34: 1.1.17 | C34: 145839 | D34: =IFERROR(VLOOKUP(C34,Tabla_APL[[STOCKCODE]:[TYPE]],3,FALSE),"") -> 4 | E34: =[5]Repuestos!F25 -> 4 | F34: =D34-E34 -> 0 | G34: JUEGO CONTACTO CONTACTOR SIZE 4 | H34: 1 | I34: =IF(H34=1,1/SUM(H$18:H$39),0) -> 0.2 | J34: 40 | K34: =$G$7-J34 -> 44779 | L34: 0 | M34: =I34*L34 -> 0 | P34: =(IF(K34<=TODAY(),1,0))*I34 -> 0.2
B35: 1.1.18 | C35: 127605 | D35: =IFERROR(VLOOKUP(C35,Tabla_APL[[STOCKCODE]:[TYPE]],3,FALSE),"") -> 5 | E35: =[5]Repuestos!F26 -> 4 | F35: =D35-E35 -> 1 | G35: GUARDA MOTOR 0.63-1 AMP | H35: 0 | I35: =IF(H35=1,1/SUM(H$18:H$39),0) -> 0 | J35: 40 | K35: =$G$7-J35 -> 44779 | L35: 0 | M35: =I35*L35 -> 0 | P35: =(IF(K35<=TODAY(),1,0))*I35 -> 0
B36: 1.1.19 | C36: 402685 | D36: =IFERROR(VLOOKUP(C36,Tabla_APL[[STOCKCODE]:[TYPE]],3,FALSE),"") -> 2 | E36: 1 | F36: =D36-E36 -> 1 | G36: INTERRUPTOR DE SEGURIDAD OTP90T3M BBA BAJA | H36: 0 | I36: =IF(H36=1,1/SUM(H$18:H$39),0) -> 0 | J36: 40 | K36: =$G$7-J36 -> 44779 | L36: 0 | M36: =I36*L36 -> 0 | P36: =(IF(K36<=TODAY(),1,0))*I36 -> 0
B37: 1.1.20 | C37: 744220 | D37: =IFERROR(VLOOKUP(C37,Tabla_APL[[STOCKCODE]:[TYPE]],3,FALSE),"") -> 0 | E37: 6 | F37: =D37-E37 -> -6 | G37: BASE PLACA SENSORES APERTURA / CIERRE | H37: 0 | I37: =IF(H37=1,1/SUM(H$18:H$39),0) -> 0 | J37: 40 | K37: =$G$7-J37 -> 44779 | L37: 0 | M37: =I37*L37 -> 0 | P37: =(IF(K37<=TODAY(),1,0))*I37 -> 0
B38: 1.1.21 | C38: 744863 | D38: =IFERROR(VLOOKUP(C38,Tabla_APL[[STOCKCODE]:[TYPE]],3,FALSE),"") -> 119 | E38: 4 | F38: =D38-E38 -> 115 | G38: BASE SOPORTE SENSOR COMPUERTA | H38: 0 | I38: =IF(H38=1,1/SUM(H$18:H$39),0) -> 0 | J38: 40 | K38: =$G$7-J38 -> 44779 | L38: 0 | M38: =I38*L38 -> 0 | P38: =(IF(K38<=TODAY(),1,0))*I38 -> 0
B39: 1.1.22 | C39: 361139 | D39: =IFERROR(VLOOKUP(C39,Tabla_APL[[STOCKCODE]:[TYPE]],3,FALSE),"") -> 0 | E39: 1 | F39: =D39-E39 -> -1 | G39: CAJA SUMADORA | H39: 0 | I39: =IF(H39=1,1/SUM(H$18:H$39),0) -> 0 | J39: 40 | K39: =$G$7-J39 -> 44779 | L39: 0 | M39: =I39*L39 -> 0 | P39: =(IF(K39<=TODAY(),1,0))*I39 -> 0
B40: 1.1 | C40: CODIGO | D40: Stock Bodega | E40: Cant. Req. | F40: EXISTENCIA | G40: REPUESTOS ELECTRICOS FEEDER FILTROS | H40: APLICA | I40: =SUM(I41:I62) -> 0 | J40: FREC | K40: DEAD LINE | L40: =AVERAGE(L41:L62) -> 13 | M40: =SUM(M41:M62) -> 0 | N40: OBSERVACIONES | O40: RQ: | P40: =SUM(P41:P62) -> 0
B41: 1.1.43 | C41: 144261 | D41: =IFERROR(VLOOKUP(C41,Tabla_APL[[STOCKCODE]:[TYPE]],3,FALSE),"") -> 84 | E41: 2 | F41: =D41-E41 -> 82 | G41: BASTON INTERRUPTOR DESALINEAMIENTO | H41: 5 | I41: =IF(H41=1,1/SUM(H$18:H$39),0) -> 0 | J41: 45 | K41: =$G$7-J41 -> 44774 | L41: 5 | M41: =I41*L41 -> 0 | P41: =(IF(K41<=TODAY(),1,0))*I41 -> 0
B42: 1.1.44 | C42: 127308 | D42: =IFERROR(VLOOKUP(C42,Tabla_APL[[STOCKCODE]:[TYPE]],3,FALSE),"") -> 0 | E42: 2 | F42: =D42-E42 -> -2 | G42: INTERRUPTOR DESALINEAMIENTO | H42: 6 | I42: =IF(H42=1,1/SUM(H$18:H$39),0) -> 0 | J42: 46 | K42: =$G$7-J42 -> 44773 | L42: 6 | M42: =I42*L42 -> 0 | P42: =(IF(K42<=TODAY(),1,0))*I42 -> 0
B43: 1.1.45 | C43: 368035 | D43: =IFERROR(VLOOKUP(C43,Tabla_APL[[STOCKCODE]:[TYPE]],3,FALSE),"") -> 0 | E43: 1 | F43: =D43-E43 -> -1 | G43: INTERRUPTOR VELOCIDAD CERO | H43: 7 | I43: =IF(H43=1,1/SUM(H$18:H$39),0) -> 0 | J43: 47 | K43: =$G$7-J43 -> 44772 | L43: 7 | M43: =I43*L43 -> 0 | P43: =(IF(K43<=TODAY(),1,0))*I43 -> 0
B44: 1.1.46 | C44: 80705 | D44: =IFERROR(VLOOKUP(C44,Tabla_APL[[STOCKCODE]:[TYPE]],3,FALSE),"") -> 3 | E44: 1 | F44: =D44-E44 -> 2 | G44: MOTOR ELECTRICO 7.5 HP 1480 RPM 380 V | H44: 8 | I44: =IF(H44=1,1/SUM(H$18:H$39),0) -> 0 | J44: 48 | K44: =$G$7-J44 -> 44771 | L44: 8 | M44: =I44*L44 -> 0 | P44: =(IF(K44<=TODAY(),1,0))*I44 -> 0
...

Sheet FODA
D1: Fortaleza
D2: Oportunidad
D3: Debilidad
D4: Amenaza
A5: ITEM | B5: FILTRO | C5: FECHA | D5: CLASIFICACIÓN | E5: GENERADO POR | F5: DESCRIPCIÓN | G5: ESPECIALIDAD | H5: PLANES DE ACCIÓN | I5: PRIORIDAD | J5: RESPONSABLE | K5: AVANCE | L5: FECHA IMPLEMENTACIÓN | M5: OBSERVACIONES
A6: 1 | B6: Filtrado | C6: 42644 | D6: Oportunidad | E6: R. Contrera | F6: Falla en accionamiento de compuerta inferior ( no evaluada, fl002) | G6: Mecanico | H6: Considerar en Hazop "Revision de accionamiento de compuerta con anticipacion para poder evaluar y proyectar tiempos de reparacion y planificacion". | I6: Alta | J6: R. Contera | K6: 1 | L6: 42675 | M6: Programado semana 26-01 al 01-02 en mantencion semanal FL003
A7: 2 | B7: Filtro 5 | C7: 42644 | D7: Debilidad | E7: A.Tolosa | F7: Realizar buena inspección antes de emitir diagnostico (actividad ducto cabezal fijo) | G7: Mecanico | H7: Considerar en Hazop la Coordinación con personal de GSO CMDIC medición a de espesores en ducto aire y agua drenaje cabezal fijo. | I7: Alta | J7: P.Perez | K7: 1 | L7: 42675 | M7: Gestionado a traves de JC.Mella
A8: 3 | B8: Filtro 5 | C8: 42644 | D8: Amenaza | E8: A. Contreras | F8: Falla de Puente Grúa durante mantenimiento Semestral impacta el cumplimiento de carta gantt. | G8: Mecanico | H8: Considerar en Hazop la Coordinación de revisión previa de puente grúa principal y auxiliar, asegurando (Certificar color del mes). | I8: Alta | J8: P.Perez | K8: 1 | L8: 42675 | M8: Gestionado a traves de JC.Mella
A9: 4 | B9: Filtro 5 | C9: 42644 | D9: Debilidad | E9: R. Segovia. | F9: Repuestos no quedan en punto de trabajo. | G9: Mecanico | H9: Incorporar el Hazop Revisión y definición de layout de repuestos en plataformas y asegurar su cumplimiento. | I9: Alta | J9: R. Segovia | K9: 1 | L9: 42736
A10: 5 | B10: Filtro 5 | C10: 42644 | D10: Debilidad | E10: R. Segovia. | F10: Herramientas no quedan en punto. | G10: Mecanico | H10: Incorporar en el Hazop la ubicación exacta donde quedan las herramientas en el área de trabajo. | I10: Alta | J10: R. Segovia | K10: 1 | L10: 42736
A11: 6 | B11: Filtro 5 | C11: 42644 | D11: Oportunidad | E11: R. Segovia. | F11: Enviar a fabricar brazos pescante o pata de cabra para cambiar VV clarkson o elastometro y liberar puente grúa. | G11: Mecanico | H11: Incorporar en Hazop el armado de pata de cabra para cambio de válvulas clarkson. | I11: Media | J11: J. Area Mec | K11: 1 | L11: 42736 | M11: Se debe diseñar y enviar a fabricar.
A12: 7 | B12: Filtro 5 | C12: 42644 | D12: Amenaza | E12: A. Contreras | F12: Placas reparadas vienen separadas en filtrante y membrana. Se requiere que esten de pares | G12: Mecanico | I12: Alta | J12: R. Segovia | K12: 1 | L12: 42675 | M12: Programado semana 26-01 al 01-02
A13: 8 | B13: Filtro 5 | C13: 42644 | D13: Oportunidad | E13: R. Segovia. | F13: Dejar todo al alcance de puente grúa auxiliar para no depender de puente principal. | G13: Mecanico | H13: Incorporar en Hazop definición de layout de distribucion de repuestos en plataforma de filtros y su seguimiento al cumplimiento. | I13: cada vez | J13: R. Segovia | K13: 1 | L13: 42736
A14: 9 | B14: Filtro 5 | C14: 42644 | D14: Oportunidad | E14: R. Segovia. | F14: Perdida de tiempo y dependencia de puente grúa para subir repuestos desde primer piso a plataforma filtros. | G14: Mecanico | H14: Incorporar el Hazop Revisión y definición de layout de repuestos en plataformas y asegurar su cumplimiento. | I14: Alta | J14: R. Segovia | K14: 1 | L14: 42736 | M14: Programado semana 02-02
A15: 10 | B15: Filtro 5 | C15: 42644 | D15: Oportunidad | E15: R. Segovia. | F15: Disponer cajones para perneria. | G15: Mecanico | H15: Implementar cajones para pernería. | I15: Media | J15: R. Harvey | K15: 0 | M15: Los cajones para pernería deben quedar en las estanterías del área filtros.
A16: 11 | B16: Filtro 5 | C16: 42644 | D16: Oportunidad | E16: C. Roa | F16: Baja Disponibilidad de maquinas de soldar. | G16: Mecanico | I16: Alta | J16: R. Villablanca | K16: 0
A17: 12 | B17: Filtro 5 | C17: 42644 | D17: Oportunidad | E17: P. Tolosa | F17: Mejorar sistema de lubricación a rodamiento compuertas lado fijo (instalando líneas, con puntos cerca del pasillo) | G17: Mecanico | H17: Incorporar en Hazop la revisión de flexibles de lubricación centralizado de lubricación de rodamientos compuertas. | I17: Alta | J17: P.Perez | K17: 1 | M17: Se debe implementar previamente. Pendiente levantamiento para compra de materiales e implementacion
A18: 13 | B18: Filtro 1 | C18: 42686 | D18: Oportunidad | E18: R.Contreras | F18: Fabricación de placas target para sensores de apertura y cierre de prensa de filtros | G18: Mecanico | K18: 1 | M18: Programado semana 02-02
A19: 14 | B19: Filtro 1 | C19: 42686 | D19: Oportunidad | E19: R.Contreras | F19: Plastificar planos del filtro y mantenerlos en terreno para las M. Semestrales. | G19: Mecanico | H19: Incorporar en Hazop la preparación dentro de la carpeta de la intervención. | I19: Media | J19: R. Segovia | K19: 1 | L19: 42736
A20: 15 | B20: Filtro 1 | C20: 42686 | D20: Debilidad | E20: R. Segovia. | F20: Tardía activación del FODA y falta de incorporación de interesados hace perder oportunidades de mejora. | G20: Mecanico | H20: Definir responsable de activación y personal que debe incorporarse. | I20: Alta | J20: R. Segovia | K20: 1 | L20: 43070 | M20: Los programadores del turno en que cae la intervención son los responsables de activar del FODA e incorporación de los interesados.
A21: 16 | B21: Filtro 1 | C21: 42686 | D21: Debilidad | E21: R. Segovia. | F21: Soportes de sensores deben estar considerados dentro de los preparativos. | G21: E&I | H21: Incorporar en el APL de Repuestos los soportes de los sensores. | I21: Media | J21: R. Segovia | K21: 1 | L21: 42736 | M21: Solicitar catalogación
A22: 17 | B22: Filtro 1 | C22: 42686 | D22: Debilidad | E22: R. Segovia. | F22: Siempre debe considerarse personal periférico para atender contingencias | G22: Mecanico | K22: 1 | M22: SE DEJO PERSONAL EXTRA PARA EL MANTENIMIENTO
A23: 18 | B23: Filtro 1 | C23: 42686 | D23: Oportunidad | E23: R. Contreras | F23: Preparar previamente líneas de lubricación para rodamientos de compuerta | G23: Mecanico | K23: 0 | M23: REPUESTO TODAVIA NO LLEGA
A24: 19 | B24: Filtro 1 | C24: 42686 | D24: Oportunidad | E24: M. Poblete | F24: Preparar jaula para cilindros de gas y acetileno en terreno | G24: Mecanico | K24: 0 | M24: SE SOLICITA COMPRA , LA CUAL SIEMENS AUN NO COMPRA.
A25: 20 | B25: Filtro 1 | C25: 42686 | D25: Debilidad | E25: M.Poblere | F25: No se considera en los preparativos el empaque cónico para vulcolet COD. 49973 | G25: Mecanico | H25: Estaba incorporado pero no se preparó. Medidas administrativas. | I25: Alta | J25: R. Segovia | K25: 1
